<?xml version="1.0"?>
<sdf version="1.6">
    <model name="uuv_hippocampus_joint">
        <!-- gazebo is handling the dynamic behaviour of this model -->
        <static>0</static>
        <link name="base_link">
            <pose>0.0 0.0 0.0 0 0 0</pose>
            <inertial>
                <pose>0 0 0 0 0 0</pose>
                <mass>1e-3</mass>
                <inertia>
                    <ixx>1e-9</ixx>
                    <ixy>0</ixy>
                    <ixz>0</ixz>
                    <iyy>1e-3</iyy>
                    <iyz>0</iyz>
                    <izz>1e-3</izz>
                </inertia>
            </inertial>
            <visual name="base_link_visual">
                <pose>0.005 0 0 0 1.5707963268 1.5707963268</pose>
                <geometry>
                    <mesh>
                        <scale>1e-3 1e-3 1e-3</scale>
                        <uri>model://uuv_hippocampus_joint/meshes/uuv_hippocampus_joint.stl</uri>
                    </mesh>
                </geometry>
                <material>
                    <script>
                        <name>Gazebo/Blue</name>
                        <uri>file://media/materials/scripts/gazebo.material</uri>
                    </script>
                </material>
            </visual>
            <gravity>0</gravity>
        </link>
        <link name="joint_link">
            <pose>0.17 0 0 0 3.1415926536 0</pose>
            <inertial>
                <pose>0 0 0 0 0 0</pose>
                <mass>1e-3</mass>
                <inertia>
                    <ixx>1e-9</ixx>
                    <ixy>0</ixy>
                    <ixz>0</ixz>
                    <iyy>1e-3</iyy>
                    <iyz>0</iyz>
                    <izz>1e-3</izz>
                </inertia>
            </inertial>
            <visual name="joint_link_visual">
                <pose>0.005 0 0 0 1.5707963268 1.5707963268</pose>
                <geometry>
                    <mesh>
                        <scale>1e-3 1e-3 1e-3</scale>
                        <uri>model://uuv_hippocampus_joint/meshes/uuv_hippocampus_joint.stl</uri>
                    </mesh>
                </geometry>
                <material>
                    <script>
                        <name>Gazebo/Blue</name>
                        <uri>file://media/materials/scripts/gazebo.material</uri>
                    </script>
                </material>
            </visual>
            <gravity>0</gravity>
        </link>

        <joint name="joint_0" type="revolute">
            <parent>base_link</parent>
            <child>joint_link</child>
            <pose>0.085 0.0 0.0 0.0 0.0 0.0</pose>
            <axis>
                <xyz>0.0 0.0 1.0</xyz>
                <use_parent_model_frame>1</use_parent_model_frame>
                <limit>
                    <lower>-2.17</lower>
                    <upper>2.17</upper>
                    <effort>1e3</effort>
                </limit>
            </axis>
        </joint>
    </model>
</sdf>
