<?xml version="1.0"?>
<sdf version="1.6">
    <model name="uuv_hippocampus_revolute_joint">
        <link name="base_link">
            <pose>0.0 0.0 0.0 0 0 0</pose>
            <visual name="base_link_visual">
                <pose>0.005 0 0 0 1.5707963268 1.5707963268</pose>
                <geometry>
                    <mesh>
                        <scale>1e-3 1e-3 1e-3</scale>
                        <uri>model://uuv_hippocampus_revolute_joint/meshes/uuv_hippocampus_joint.stl</uri>
                    </mesh>
                </geometry>
                <material>
                    <script>
                        <name>Gazebo/Blue</name>
                        <uri>file://media/materials/scripts/gazebo.material</uri>
                    </script>
                </material>
            </visual>
            <gravity>0</gravity>
        </link>
        <link name="opp_link">
            <pose>0.17 0 0 0 3.1415926536 0</pose>
            <visual name="opp_link_visual">
                <pose>0.005 0 0 0 1.5707963268 1.5707963268</pose>
                <geometry>
                    <mesh>
                        <scale>1e-3 1e-3 1e-3</scale>
                        <uri>model://uuv_hippocampus_revolute_joint/meshes/uuv_hippocampus_joint.stl</uri>
                    </mesh>
                </geometry>
                <material>
                    <script>
                        <name>Gazebo/Blue</name>
                        <uri>file://media/materials/scripts/gazebo.material</uri>
                    </script>
                </material>
            </visual>
            <gravity>0</gravity>
        </link>

        <joint name="joint_0" type="revolute">
            <parent>base_link</parent>
            <child>opp_link</child>
            <pose>0.085 0.0 0.0 0.0 0.0 0.0</pose>
            <axis>
                <xyz>0.0 0.0 1.0</xyz>
                <limit>
                    <lower>-2.17</lower>
                    <upper>2.17</upper>
                    <effort>1e3</effort>
                </limit>
            </axis>
        </joint>
    </model>
</sdf>
